Workbook
Name Print_Area: 'КС-2 №1'!$B$1:$H$53
Name Print_Area: 'КС-3 №1'!$A$1:$F$37
Name Print_Titles: 'КС-2 №1'!$28:$28
Name ЕдИзм: #REF!
Name код: #REF!
Name Работа: OFFSET(#REF!,MATCH(#REF!,#REF!,0)-1,1,COUNTIF(#REF!,#REF!),1)
Name Способ_учета: #REF!

Sheet КС-2 №1
J1: Унифицированная форма №КС-2
J2: Утверждена постановлением Госкомстата России
J3: от 11.11.99. № 100
J4: Код
I5: Форма по ОКУД | J5: 322001
A7: Застройщик: | D7: Общество с ограниченной ответственностью «Специализированный застройщик «АСПЕЙС Хорошевская», 123112 , г. Москва, наб. Пресненская, д. 6, стр. 2, помещение 34/38 | I7: по ОКПО | J7: 74641884
D8: организация, адрес, телефон, факс
A9: Технический Заказчик: | D9: Общество с ограниченной ответственностью «А Плюс», 127006, г. Москва, ул. Малая Дмитровка, 18Ас3, пом. 1/3 | I9: по ОКПО | J9: 99975557
D10: организация, адрес, телефон, факс
A11: Генподрядчик: | D11: Общество с ограниченной ответственностью «ЛегендаЭлит», 109028, г. Москва, пер. Дурасовский, д. 5, стр. 2 | I11: по ОКПО | J11: 47810841
D12: организация, адрес, телефон, факс
A13: Стройка: | D13: Бизнес-центр с подземным паркингом по адресу: г. Москва, шоссе Хорошёвское, вл. 39
D14: наименование, адрес
A15: Объект: | D15: =D13 -> Бизнес-центр с подземным паркингом по адресу: г. Москва, шоссе Хорошёвское, вл. 39
D16: наименование | I16: Вид деятельности по ОКДП
H17: Договор генподряда | I17: номер | J17: АСП-ХОР/2025
I18: дата | J18: 22.09.2025 г.
I19: Вид операции
G21: Номер документа | H21: Дата составления | I21: Отчетный период
I22: с | J22: по
D23: AKT | G23: 1 | H23: 45961 | I23: 45922 | J23: =H23 -> 45961
D24: О ПРИЕМКЕ ВЫПОЛНЕННЫХ РАБОТ
A25: Основание: | C25: Выполнение комплекса строительно-монтажных работ по возведению монолитных ж/б конструкций - фундаментная плита 1 и 2 корпус. Калькуляция №3.
A27: Код затрат | B27: № п/п | C27: № п/п по смете | D27: Наименование работ и затрат | E27: Ед. изм. | F27: Объем | G27: Цена за ед., руб. с НДС (20%) | H27: Общая стоимость, руб. с НДС (20%) | I27: Расход на единицу | J27: Примечание
A28: 1 | B28: 2 | C28: 3 | D28: 4 | E28: 5 | F28: 6 | G28: 7 | H28: 8 | I28: 9 | J28: 10
D29: Раздел 2. Фундаментная плита - 2 корпус
A30: СР2030 | B30: =B29+1 -> 1 | C30: 41 | D30: Доработка грунта до проектной отметки вручную и вывозом грунта за пределы строительной площадки | E30: м3 | F30: =43.16+8.46 -> 51.62 | G30: 1725 | H30: =ROUND(F30*G30,2) -> 89044.5
A31: СР2030 | B31: =B30+1 -> 2 | C31: 42 | D31: Устройство армированной бетонной подготовки т. 350 мм | E31: м3 | F31: 139.45 | G31: 13500 | H31: =ROUND(F31*G31,2) -> 1882575
A32: СР2030 | B32: =B31+1 -> 3 | C32: 43 | D32: Бетон B25 F150 W8 на гранитном щебне по ГОСТ 26633-2015 | E32: м3 | F32: 142.5 | G32: 7070 | H32: =ROUND(F32*G32,2) -> 1007475 | I32: 1.022
A33: СР2030 | B33: =B32+1 -> 4 | C33: 45 | D33: Арматура Ø 12 А500С (100х100 мм) | E33: тн | F33: =ROUND(105.29*F31/767.3,2) -> 19.14 | G33: 45900 | H33: =ROUND(F33*G33,2) -> 878526 | I33: 1.033
A34: СР2030 | B34: =B33+1 -> 5 | C34: 46 | D34: Мембрана профилироваанная Planter Eco | E34: м2 | F34: 392.3 | G34: 92 | H34: =ROUND(F34*G34,2) -> 36091.6 | I34: 1.1
D35: Раздел 3. Фундаментная плита под башенный кран №3
A36: СР2030 | B36: =B34+1 -> 6 | C36: 98 | D36: Устройство бетонной подготовки т.100 мм | E36: м3 | F36: 5.2 | G36: 7000 | H36: =ROUND(F36*G36,2) -> 36400
A37: СР2030 | B37: =B36+1 -> 7 | C37: 99 | D37: Бетон B7,5 П4 F50 W2 (С.9-2) на гравийном щебне по ГОСТ 26633-2015 | E37: м3 | F37: 6 | G37: 6383.33 | H37: =ROUND(F37*G37,2) -> 38299.98 | I37: =F37/F36 -> 1.1538462
A38: СР2030 | B38: =B37+1 -> 8 | C38: 100 | D38: Устройство фундаментной плиты т.1500 мм | E38: м3 | F38: 73.5 | G38: 19500 | H38: =ROUND(F38*G38,2) -> 1433250
A39: СР2030 | B39: =B38+1 -> 9 | C39: 101 | D39: Бетон B25 F150 W8 на гравийном щебне по ГОСТ 26633-2015 | E39: м3 | F39: =ROUND(F38*I39,2) -> 74.6 | G39: 6850 | H39: =ROUND(F39*G39,2) -> 511010 | I39: 1.015
A40: СР2030 | B40: =B39+1 -> 10 | C40: 102 | D40: Арматура ф16 А500С ГОСТ 34028-2016 | E40: тн | F40: 0.56 | G40: 45400 | H40: =ROUND(F40*G40,2) -> 25424 | I40: 1.033
A41: СР2030 | B41: =B40+1 -> 11 | C41: 103 | D41: Арматура ф20 А500С ГОСТ 34028-2016 | E41: тн | F41: 1.51 | G41: 45400 | H41: =ROUND(F41*G41,2) -> 68554 | I41: 1.033
A42: СР2030 | B42: =B41+1 -> 12 | C42: 104 | D42: Арматура ф25 А500С ГОСТ 34028-2016 | E42: тн | F42: 5.2 | G42: 45400 | H42: =ROUND(F42*G42,2) -> 236080 | I42: 1.033 | K42: =78.5*K43 -> 353.25
A43: СР2030 | B43: =B42+1 -> 13 | C43: 105 | D43: Лист г/к 10мм ГОСТ 19903-2015 | E43: тн | F43: 0.13 | G43: =ROUND(23052/0.35325,2) -> 65256.9 | H43: =ROUND(F43*G43,2) -> 8483.4 | I43: 1.033 | J43: 1м2=78,5кг, 1 лист 353,25 кг | K43: =3*1.5 -> 4.5 | L43: =23052/K42 -> 65.2569
...

Sheet КС-3 №1
F1: Унифицированная форма № КС-3
F2: Утверждена постановлением Госкомстата России
F3: от 11.11.99 № 100
E4: Код
D5: Форма по ОКУД | E5: 0322001
A6: Застройщик: Общество с ограниченной ответственностью «Специализированный застройщик «АСПЕЙС Хорошевская», 123112 , г. Москва, наб. Пресненская, д. 6, стр. 2, помещение 34/38 | D6: по ОКПО | E6: 74641884
A7: Технический Заказчик: Общество с ограниченной ответственностью «А Плюс», 127006, г. Москва, ул. Малая Дмитровка, 18Ас3, пом. 1/3 | D7: по ОКПО | E7: 99975557
A8: Генподрядчик: Общество с ограниченной ответственностью «ЛегендаЭлит», 109028, г. Москва, пер. Дурасовский, д. 5, стр. 2 | D8: по ОКПО | E8: 47810841
A9: Объект: Бизнес-центр с подземным паркингом по адресу: г. Москва, шоссе Хорошёвское, вл. 39 | D9: по ОКПО
D10: Вид деятельности по ОКДП
C11: Договор подряда (контракт) | D11: номер | E11: АСП-ХОР/2025
D12: дата | E12: 22.09.2025 г.
D13: Вид операции
C15: Номер документа | D15: Дата составления | E15: Отчётный период
E16: с | F16: по
B17: Справка | C17: 1 | D17: ='КС-2 №1'!H23 -> 45961 | E17: 22.09.2025 г. | F17: =D17 -> 45961
A18: о стоимости выполненных работ и затрат
A20: Номер по порядку | B20: Наименование пусковых комплексов, этапов, объектов, видов выполненных работ, оборудования, затрат | C20: Код | D20: Стоимость выполненных работ и затрат, руб
D21: с начала проведения работ | E21: с начала года | F21: в том числе за отчетный период
A22: 1 | B22: 2 | C22: 3 | D22: 4 | E22: 5 | F22: 6
A23: 1 | B23: Всего работ и затрат, включаемых в стоимость работ | D23: =D25 -> 5214965.3 | E23: =E25 -> 5214965.3 | F23: =F25 -> 5214965.3
B24: в том числе:
A25: 2 | B25: Акт №1. Выполнение комплекса строительно-монтажных работ по возведению монолитных ж/б конструкций - фундаментная плита 1 и 2 корпус. Калькуляция №3 | D25: =F25 -> 5214965.3 | E25: =F25 -> 5214965.3 | F25: ='КС-2 №1'!H45-'КС-2 №1'!H46 -> 5214965.3
E26: Итого: | F26: =F25 -> 5214965.3
E27: Сумма НДС (20%) | F27: =F26*20% -> 1042993.1
E28: Всего с учетом НДС (20%): | F28: =F26+F27 -> 6257958.3
A30: Застройщик: | B30: ООО «СЗ «АСПЕЙС Хорошевская» в лице Генерального директора управляющей организации ООО «АСПЕЙС Девелопмент» | E30: О.В. Смирнов
B31: должность | C31: подпись | E31: расшифровка подписи
B32: М.П.
A35: Технический Заказчик: | B35: Генеральный директор ООО «А+» | E35: Е.С. Воронин
B36: должность | C36: подпись | E36: расшифровка подписи
B37: М.П.
A40: Генподрядчик: | B40: Генеральный директор ООО «ЛегендаЭлит» | E40: Дылюк А.
B41: должность | C41: подпись | E41: расшифровка подписи
B42: М.П.

Sheet Удержания
A1: РАСЧЕТ СУММЫ ПОГАШЕНИЯ АВАНСОВ и ГАРАНТИЙНОГО УДЕРЖАНИЯ
A2: за октябрь 2025 г.
A3: на объекте: Бизнес-центр с подземным паркингом по адресу: г. Москва, шоссе Хорошёвское, вл. 39
A4: Всего работ и затрат, включаемых в стоимость работ в том числе: | B4: Сумма работ по акту КС-2, руб. | C4: Использовано материалов (по актам КС-2), руб. | D4: Закрытие авансов | I4: Удержание 3%, руб. | J4: Итого к оплате, руб.
D5: Полученный аванс, руб. | E5: № п/п, дата | F5: Незакрытый остаток прошлого периода, руб. | G5: Сумма закрытия, руб. | H5: Остаток к закрытию следующего периода, руб.
A6: 1 | B6: 2 | C6: 3 | D6: 4 | E6: 5 | F6: 6 | G6: 7 | H6: 8 | I6: 9 | J6: 10
A7: Всего работ и затрат в текущих ценах:
A8: Разработка и согласование ППРпс и проекта на фундамент под башенные краны. Мобилизация и демобилизация башенных кранов. Калькуляция №1 (ООО "СМП ТРЭЙД") | D8: 1956000 | E8: 443 от 09.10.2025 г. | F8: 1956000 | H8: =F8-G8 -> 1956000 | I8: =ROUND(B8*3%,2) -> 0 | J8: =B8-G8-G9-I8 -> 0 | K8: БК№3
D9: 515000 | E9: 444 от 09.10.2025 г. | F9: 515000 | H9: =F9-G9 -> 515000 | K9: ППРпс
A10: Монтаж виброизоляции Калькуляция №2 (ООО "Гавари Трейд") | D10: 2433535.5 | E10: 510 от 21.10.2025 г. | F10: 2433535.5 | H10: =F10-G10 -> 2433535.5 | I10: =ROUND(B10*3%,2) -> 0 | J10: =B10-G10-I10 -> 0 | K10: виброзащита (работа)
A11: КС-2 №1. Выполнение комплекса строительно-монтажных работ по возведению монолитных ж/б конструкций - фундаментная плита 1 и 2 корпус. Калькуляция №3 | B11: ='КС-2 №1'!H45 -> 6257958.3 | C11: ='КС-2 №1'!K45 -> 2816688.8 | D11: 5000000 | E11: 871 от 12.08.2025 г. (соглашение №1 от 30.09.2025 г. к дог. № 1АС/ХОР - зачет аванса) | F11: =D11 -> 5000000 | G11: 1327091.9 | H11: =F11-G11 -> 3672908.1 | I11: =ROUND(B11*3%,2) -> 187738.75 | J11: =B11-G11-G12-G13-G14-G15-G16-G17-I11 -> 1962530.5 | K11: монолит (работа, гидроизоляция) | N11: =F12+F11+F16 -> 50000000 | O11: 1.3337438e+08
D12: 19000000 | E12: 926 от 21.08.2025 г. (соглашение №1 от 30.09.2025 г. к дог. № 1АС/ХОР - зачет аванса) | F12: =D12 -> 19000000 | H12: =F12-G12 -> 19000000 | K12: монолит (работа, гидроизоляция) | N12: =N11/O11 -> 0.3748846 | O12: ='КС-2 №1'!K49+'КС-2 №1'!K48 -> 3477361.1 | P12: =N12*O12 -> 1303609.1
D13: 25703400 | E13: 445 от 09.10.2025 г. | F13: =D13 -> 25703400 | G13: ='КС-2 №1'!K46 -> 1223812.2 | H13: =F13-G13 -> 24479588 | K13: металлопрокат
D14: 5000000 | E14: 446 от 09.10.2025 г. | F14: =D14 -> 5000000 | G14: ='КС-2 №1'!K47 -> 1556785 | H14: =F14-G14 -> 3443215 | K14: бетон
D15: 2454614 | E15: 447 от 09.10.2025 г. | F15: =D15 -> 2454614 | H15: =F15-G15 -> 2454614 | K15: каркас
D16: 26000000 | E16: 498 от 16.10.2025 г. | F16: =D16 -> 26000000 | H16: =F16-G16 -> 26000000 | K16: монолит (работа, гидроизоляция)
D17: 5000032 | E17: 515 от 23.10.2025 г. | F17: =D17 -> 5000032 | H17: =F17-G17 -> 5000032 | K17: бетон
A19: Всего: | B19: =SUM(B7:B18) -> 6257958.3 | C19: =SUM(C7:C18) -> 2816688.8 | D19: =SUM(D7:D18) -> 93062581 | F19: =SUM(F7:F18) -> 93062581 | G19: =SUM(G7:G18) -> 4107689.1 | H19: =SUM(H7:H18) -> 88954892 | I19: =SUM(I7:I18) -> 187738.75 | J19: =SUM(J7:J18) -> 1962530.5
A20: в том числе НДС 20% | B20: =ROUND(B19*20/120,2) -> 1042993.1 | C20: =ROUND(C19*20/120,2) -> 469448.14 | D20: =ROUND(D19*20/120,2) -> 15510430 | F20: =ROUND(F19*20/120,2) -> 15510430 | G20: =ROUND(G19*20/120,2) -> 684614.85 | H20: =ROUND(H19*20/120,2) -> 14825815 | I20: =ROUND(I19*20/120,2) -> 31289.79 | J20: =ROUND(J19*20/120,2) -> 327088.41
A22: Застройщик: | B22: ООО «СЗ «АСПЕЙС Хорошевская» в лице Генерального директора управляющей организации ООО «АСПЕЙС Девелопмент» | G22: О.В. Смирнов
B23: должность | E23: подпись | G23: расшифровка подписи
B24: М.П.
A27: Технический Заказчик: | B27: Генеральный директор ООО «А+» | G27: Е.С. Воронин
B28: должность | E28: подпись | G28: расшифровка подписи
B29: М.П.
A32: Генподрядчик: | B32: Генеральный директор ООО «ЛегендаЭлит» | G32: Дылюк А.
B33: должность | E33: подпись | G33: расшифровка подписи
B34: М.П.
